Workbook

Sheet Humanitarian codes
A1: Codes
A2: CC
A3: DP
A4: DR
A5: DX
A6: EP
A7: MP
A8: RA
A9: SM
A10: SN

Sheet Org List
A1: Organisation | B1: Country | C1: Org type | I1: destination_orgtype
A2: ACTED | B2: Afghanistan | C2: NGOs: International | I2: Governments: Local
A3: CESVI | B3: Afghanistan | C3: NGOs: International | I3: Governments: National
A4: Norwegian Refugee Council NRC | B4: Afghanistan | C4: NGOs: International | I4: Multilateral: Other
A5: ORGANIZATION FOR HEALTH PROMOTION | B5: Afghanistan | C5: NGOs: National | I5: Multilateral: UN
A6: RELIEF HUMANITARIAN DEVELOPMENT | B6: Afghanistan | C6: NGOs: National | I6: NGOs: International
A7: ASOCIACION CIVIL ALIANZA POR VENEZU | B7: Argentina | C7: NGOs: National | I7: NGOs: Internationally Affiliated
A8: ASOCIACION MUTUAL ISRAELITA ARGENTI | B8: Argentina | C8: NGOs: National | I8: NGOs: Local
A9: ASOCIACION PSICOANALITICA DE BUENOS | B9: Argentina | C9: NGOs: National | I9: NGOs: National
A10: ASOENVEAR ASOCIACION DE ENFERMEROS | B10: Argentina | C10: NGOs: National | I10: Other
A11: ASOMEVENAR ASOCIACION CIVIL MEDICOS | B11: Argentina | C11: NGOs: National | I11: Other: Multiple Organisations
A12: CRUZ ROJA ARGENTINA | B12: Argentina | C12: Red Cross: National | I12: Other: Unknown
... A19: FUSA PARA LA SALUD INTEG AC | B19: Argentina | C19: NGOs: National | I19: Red Cross: National
A20: INICIA EMPRENDER PARA EL FUTURO | B20: Argentina | C20: NGOs: National
A21: Fundacion Venearuba Solidaria | B21: Aruba (Kingdom of the Netherlands) | C21: NGOs: National
A22: International Detention Coalition | B22: Australia | C22: NGOs: International
A23: ACTION AID BANGLADESH | B23: Bangladesh | C23: NGOs: International
A24: ACTION CONTRE LA FAIM (ACF) | B24: Bangladesh | C24: NGOs: International
A25: BANGLA-GERMAN SAMPREETI | B25: Bangladesh | C25: NGOs: National
A26: BNWLA | B26: Bangladesh | C26: NGOs: National
A27: BRAC | B27: Bangladesh | C27: NGOs: National
A28: CARE BANGLADESH | B28: Bangladesh | C28: NGOs: International
A29: CARITAS BANGLADESH | B29: Bangladesh | C29: NGOs: Internationally affiliated
A30: DEPARTMENT GEOLOGY | B30: Bangladesh | C30: Unknown
A31: DSK | B31: Bangladesh | C31: NGOs: National
... A1005: GENESIS ENTREPRENEURSHIP TRUST | B1005: Zimbabwe | C1005: NGOs: National

Sheet 2022
A1: Year | B1: Project ID | C1: Project Title | D1: Project Type | E1: Purchasing Country | F1: Purchase Order or Contract Number | G1: Title of the Purchase Order or Contract | H1: Procurement, IP or GRE? | I1: Counterpart Name | J1: Counterpart Location | K1: Value of PO/Contract per Project (USD) | L1: Total Value of PO/Contract (USD) | M1: Humanitarian
A2: 2022 | B2: CD.0071 | C2: SME Boost: Economic Integration of Internally Displaced People and Business Recovery (via IOM to Mitigate the COVID-19 Crisis) | D2: MIGRATION AND DEVELOPMENT | E2: Ukraine | F2: 4500239100 | G2: Grant_SME Boost_LLC "Brand Roomio", Lviv region | H2: Grant Awards | I2: LLC BREND ROOMIO | J2: Ukraine | K2: 40568 | L2: 40568 | M2: =IFERROR(IF(VLOOKUP(LEFT(B2,2),'Humanitarian codes'!$A$2:$A$10,1,FALSE)=LEFT(B2,2),"Yes","Error"),"No") -> No
A3: 2022 | B3: CD.0071 | C3: SME Boost: Economic Integration of Internally Displaced People and Business Recovery (via IOM to Mitigate the COVID-19 Crisis) | D3: MIGRATION AND DEVELOPMENT | E3: Ukraine | F3: 4500239488 | G3: Grant_SME Boost_PE Pyvovar Serhii, Lviv | H3: Grant Awards | I3: PE Pyvovar Serhii L. | J3: Ukraine | K3: 40568 | L3: 40568 | M3: =IFERROR(IF(VLOOKUP(LEFT(B3,2),'Humanitarian codes'!$A$2:$A$10,1,FALSE)=LEFT(B3,2),"Yes","Error"),"No") -> No | S3: Value of PO/Contract per Project (USD)
A4: 2022 | B4: CD.0071 | C4: SME Boost: Economic Integration of Internally Displaced People and Business Recovery (via IOM to Mitigate the COVID-19 Crisis) | D4: MIGRATION AND DEVELOPMENT | E4: Ukraine | F4: 4500240362 | G4: Grant_SME Boost_PE Liubchenko Vladyslav, Lviv | H4: Grant Awards | I4: PE Liubchenko Vladyslav V. | J4: Ukraine | K4: 40568 | L4: 40568 | M4: =IFERROR(IF(VLOOKUP(LEFT(B4,2),'Humanitarian codes'!$A$2:$A$10,1,FALSE)=LEFT(B4,2),"Yes","Error"),"No") -> No | S4: Total Value of PO/Contract (USD)
A5: 2022 | B5: CD.0071 | C5: SME Boost: Economic Integration of Internally Displaced People and Business Recovery (via IOM to Mitigate the COVID-19 Crisis) | D5: MIGRATION AND DEVELOPMENT | E5: Ukraine | F5: 4500241579 | G5: Grant_SME Boost_## SPO Melitopolproekt engineering, Zaporizhya region | H5: Grant Awards | I5: PE SPO MELITOPOLPROEKT ENGINEERING | J5: Ukraine | K5: 40568 | L5: 40568 | M5: =IFERROR(IF(VLOOKUP(LEFT(B5,2),'Humanitarian codes'!$A$2:$A$10,1,FALSE)=LEFT(B5,2),"Yes","Error"),"No") -> No
A6: 2022 | B6: CD.0071 | C6: SME Boost: Economic Integration of Internally Displaced People and Business Recovery (via IOM to Mitigate the COVID-19 Crisis) | D6: MIGRATION AND DEVELOPMENT | E6: Ukraine | F6: 4500242845 | G6: UA1-2022-5615_Grant_SME Boost_PE BONDAR V.V._Zakarpattia | H6: Grant Awards | I6: PE Bondar Valerii V. | J6: Ukraine | K6: 40568 | L6: 40568 | M6: =IFERROR(IF(VLOOKUP(LEFT(B6,2),'Humanitarian codes'!$A$2:$A$10,1,FALSE)=LEFT(B6,2),"Yes","Error"),"No") -> No | S6: Column K (contract per project) shows value of individual projects within the larger funding amount
A7: 2022 | B7: CD.0071 | C7: SME Boost: Economic Integration of Internally Displaced People and Business Recovery (via IOM to Mitigate the COVID-19 Crisis) | D7: MIGRATION AND DEVELOPMENT | E7: Ukraine | F7: 4500243287 | G7: UA1-2022-5628_Grant_SME Boost_LLC KYIVTEKHMET | H7: Grant Awards | I7: LLC KYIVTEKHMET | J7: Ukraine | K7: 40080 | L7: 40080 | M7: =IFERROR(IF(VLOOKUP(LEFT(B7,2),'Humanitarian codes'!$A$2:$A$10,1,FALSE)=LEFT(B7,2),"Yes","Error"),"No") -> No | S7: Column L (contract) shows the total value of the larger funding amount (multiple projects, or recipients)
A8: 2022 | B8: CD.0071 | C8: SME Boost: Economic Integration of Internally Displaced People and Business Recovery (via IOM to Mitigate the COVID-19 Crisis) | D8: MIGRATION AND DEVELOPMENT | E8: Ukraine | F8: 4500270675 | G8: Implementation of the SME boost grant projectEnter text here... | H8: Grant Awards | I8: PP NVF KVOTA | J8: Ukraine | K8: 41365 | L8: 41365 | M8: =IFERROR(IF(VLOOKUP(LEFT(B8,2),'Humanitarian codes'!$A$2:$A$10,1,FALSE)=LEFT(B8,2),"Yes","Error"),"No") -> No
A9: 2022 | B9: DP.2413 | C9: Support to Displaced Afghans in Pakistan, Iran, Central Asia, and Afghanistan | D9: MOVEMENT, EMERGENCY AND POST-CRISIS MIGRATION MANAGEMENT | E9: Tajikistan | F9: 4500243699 | G9: Hiring of Implementing partners for provision of logistical and technical support to IOM within the project "Support to Displaced Af ghans in Pakistan, Iran, Central Asia, and Afghanistan” Reference Documents: PR No.: 4200302087 dated 04 August 2022 Pro | H9: Grant Awards | I9: NGO Femida | J9: Tajikistan | K9: 51278 | L9: 51278 | M9: =IFERROR(IF(VLOOKUP(LEFT(B9,2),'Humanitarian codes'!$A$2:$A$10,1,FALSE)=LEFT(B9,2),"Yes","Error"),"No") -> Yes
A10: 2022 | B10: DP.2413 | C10: Support to Displaced Afghans in Pakistan, Iran, Central Asia, and Afghanistan | D10: MOVEMENT, EMERGENCY AND POST-CRISIS MIGRATION MANAGEMENT | E10: Tajikistan | F10: 4500243703 | G10: Hiring of Implementing partners for provision of logistical and technical support to IOM within the project "Support to Displaced Af ghans in Pakistan, Iran, Central Asia, and Afghanistan" Reference Documents: PR No.: 4200302087 dated 04 August 2022 Pro | H10: Grant Awards | I10: Women & Society | J10: Tajikistan | K10: 26577 | L10: 26577 | M10: =IFERROR(IF(VLOOKUP(LEFT(B10,2),'Humanitarian codes'!$A$2:$A$10,1,FALSE)=LEFT(B10,2),"Yes","Error"),"No") -> Yes
A11: 2022 | B11: DP.2423 | C11: Emergency Multi-Purpose Cash Assistance to Vulnerable Households in Tonga | D11: MOVEMENT, EMERGENCY AND POST-CRISIS MIGRATION MANAGEMENT | E11: Tonga | F11: 4500197484 | G11: Interim Report | H11: Grant Awards | I11: MORDI Tonga Trust | J11: Tonga | K11: 200000 | L11: 200000 | M11: =IFERROR(IF(VLOOKUP(LEFT(B11,2),'Humanitarian codes'!$A$2:$A$10,1,FALSE)=LEFT(B11,2),"Yes","Error"),"No") -> Yes
A12: 2022 | B12: DP.2452 | C12: Lifesaving Assistance for Conflict-Affected People in Ukraine and Neighbouring Countries | D12: MOVEMENT, EMERGENCY AND POST-CRISIS MIGRATION MANAGEMENT | E12: Poland | F12: 4500220613 | G12: Implementing partner agreement as per PR 4200245571 | H12: Grant Awards | I12: Unitatem Foundation | J12: Poland | K12: 110733 | L12: 510787 | M12: =IFERROR(IF(VLOOKUP(LEFT(B12,2),'Humanitarian codes'!$A$2:$A$10,1,FALSE)=LEFT(B12,2),"Yes","Error"),"No") -> Yes
A13: 2022 | B13: DP.2452 | C13: Lifesaving Assistance for Conflict-Affected People in Ukraine and Neighbouring Countries | D13: MOVEMENT, EMERGENCY AND POST-CRISIS MIGRATION MANAGEMENT | E13: Poland | F13: 4500220641 | G13: IP - Agreement - The Central Council of Roma | H13: Grant Awards | I13: Centralna Rada Romow w Polsce | J13: Poland | K13: 165127 | L13: 165127 | M13: =IFERROR(IF(VLOOKUP(LEFT(B13,2),'Humanitarian codes'!$A$2:$A$10,1,FALSE)=LEFT(B13,2),"Yes","Error"),"No") -> Yes
A14: 2022 | B14: DP.2465 | C14: IOM Flash Appeal for Ukraine and Neighboring Countries | D14: MOVEMENT, EMERGENCY AND POST-CRISIS MIGRATION MANAGEMENT | E14: Belarus | F14: 4500267537 | G14: Grant to implementing partner | H14: Grant Awards | I14: Movement of Medical Workers | J14: Belarus | K14: 12111 | L14: 141085 | M14: =IFERROR(IF(VLOOKUP(LEFT(B14,2),'Humanitarian codes'!$A$2:$A$10,1,FALSE)=LEFT(B14,2),"Yes","Error"),"No") -> Yes
A15: 2022 | B15: DP.2465 | C15: IOM Flash Appeal for Ukraine and Neighboring Countries | D15: MOVEMENT, EMERGENCY AND POST-CRISIS MIGRATION MANAGEMENT | E15: Poland | F15: 4500220613 | G15: Implementing partner agreement as per PR 4200245571 | H15: Grant Awards | I15: Unitatem Foundation | J15: Poland | K15: 380051 | L15: 510787 | M15: =IFERROR(IF(VLOOKUP(LEFT(B15,2),'Humanitarian codes'!$A$2:$A$10,1,FALSE)=LEFT(B15,2),"Yes","Error"),"No") -> Yes
A16: 2022 | B16: DP.2470 | C16: IOM Flash Appeal for Ukraine and Neighbouring Countries 2022 - Norway | D16: MOVEMENT, EMERGENCY AND POST-CRISIS MIGRATION MANAGEMENT | E16: Poland | F16: 4500220613 | G16: Implementing partner agreement as per PR 4200245571 | H16: Grant Awards | I16: Unitatem Foundation | J16: Poland | K16: 20003 | L16: 510787 | M16: =IFERROR(IF(VLOOKUP(LEFT(B16,2),'Humanitarian codes'!$A$2:$A$10,1,FALSE)=LEFT(B16,2),"Yes","Error"),"No") -> Yes
A17: 2022 | B17: FC.0174 | C17: Strengthening Socio-Economic Reincorporation Initiatives for Sustainability in Colombia | D17: MOVEMENT, EMERGENCY AND POST-CRISIS MIGRATION MANAGEMENT | E17: Colombia | F17: 4500224170 | G17: GRANT No.35 DE 2022 35 CM 356 FC.0180 FC.0174 12628916 COOPERATIVA MULTIACTIVA DE PAZ DEL TOTAL VALUE: COP 367.706.770 IOM CONTRIB: COP 367.706.770 | H17: Grant Awards | I17: COOPERATIVA MULTIACTIVA DE PAZ DEL | J17: Colombia | K17: 85268 | L17: 103526 | M17: =IFERROR(IF(VLOOKUP(LEFT(B17,2),'Humanitarian codes'!$A$2:$A$10,1,FALSE)=LEFT(B17,2),"Yes","Error"),"No") -> No
A18: 2022 | B18: FC.0180 | C18: Peace and Reconciliation Environments | D18: MOVEMENT, EMERGENCY AND POST-CRISIS MIGRATION MANAGEMENT | E18: Colombia | F18: 4500205288 | G18: GRANT 32 DE 2022 CM-356 FC.0180 12628790 COOPERATIVA MULTIACTIVA MEMORIA, VI TOTAL VALUE: COP 211.998.032 IOM CONTRIB: COP 211.998.032 | H18: Grant Awards | I18: COOPERATIVA MULTIACTIVA MEMORIA, VI | J18: Colombia | K18: 56639 | L18: 56639 | M18: =IFERROR(IF(VLOOKUP(LEFT(B18,2),'Humanitarian codes'!$A$2:$A$10,1,FALSE)=LEFT(B18,2),"Yes","Error"),"No") -> No
A19: 2022 | B19: FC.0180 | C19: Peace and Reconciliation Environments | D19: MOVEMENT, EMERGENCY AND POST-CRISIS MIGRATION MANAGEMENT | E19: Colombia | F19: 4500224170 | G19: GRANT No.35 DE 2022 35 CM 356 FC.0180 FC.0174 12628916 COOPERATIVA MULTIACTIVA DE PAZ DEL TOTAL VALUE: COP 367.706.770 IOM CONTRIB: COP 367.706.770 | H19: Grant Awards | I19: COOPERATIVA MULTIACTIVA DE PAZ DEL | J19: Colombia | K19: 18258 | L19: 103526 | M19: =IFERROR(IF(VLOOKUP(LEFT(B19,2),'Humanitarian codes'!$A$2:$A$10,1,FALSE)=LEFT(B19,2),"Yes","Error"),"No") -> No
... A1747: 2022 | B1747: TK.0025 | C1747: Strengthening the Institutional Offer for Colombians Abroad and Their Diasporic Communities, to Enhance Their Contribution to Sustainable Development | D1747: MIGRATION AND DEVELOPMENT | E1747: Colombia | F1747: 4500252066 | G1747: CONVENIO FGM-044-002 2022 12629082 CORPORACION LA GRAN COLOMBIA TOTAL VALUE: COP 194.514.727 IOM CONTRIB: COP 150.000.000 PRO CONTRIB: COP 44.514.727 | H1747: Implementing Partners | I1747: CORPORACION LA GRAN COLOMBIA | J1747: Colombia | K1747: 33011 | L1747: 33011 | M1747: =IFERROR(IF(VLOOKUP(LEFT(B1747,2),'Humanitarian codes'!$A$2:$A$10,1,FALSE)=LEFT(B1747,2),"Yes","Error"),"No") -> No

Sheet 2023
A1: Year and Quarter | B1: Project ID | C1: Project Title / Project Description | D1: Project Type | E1: Purchasing Country | F1: Title of the Purchase Order or Contract | G1: PO Number | H1: PO Type / Procurement, IP or GRE? | I1: Counterpart Name | J1: Counterpart Location | K1: Sum of Value in USD (Charged to the Project) / PO Value per Project (USD) | L1: Total PO/Contract Value in USD/Total PO Value in USD | M1: Humanitarian
A2: 2023 Q4 | B2: DP.2659 | C2: Provision of Humanitarian Coordination, Shelter and Settlements, Water, Sanitation and Hygiene (WASH), Multi-Purpose Cash Assistance (MPCA), Health and Protection Assistance for Crisis-Affected Populations in Ethiopia | D2: MOVEMENT, EMERGENCY AND POST-CRISIS MIGRATION MANAGEMENT | E2: Ethiopia | G2: 4500364246 | H2: Entity Grants | I2: Tigray Youth Empowerment Solutions | J2: Ethiopia | K2: 29267 | L2: 31325 | M2: =IFERROR(IF(VLOOKUP(LEFT(B2,2),'Humanitarian codes'!$A$2:$A$10,1,FALSE)=LEFT(B2,2),"Yes","Error"),"No") -> Yes
A3: 2023 Q4 | B3: RR.0281 | C3: Nigeria: Managing Migration through Development (MMDP) 2.0 in Edo State | D3: REGULATING MIGRATION | E3: Nigeria | G3: 4500357036 | H3: Entity Grants | I3: EDO STATE SKILLS DEVELOPMENT AGENCY | J3: Nigeria | K3: 42140 | L3: 45103.68 | M3: =IFERROR(IF(VLOOKUP(LEFT(B3,2),'Humanitarian codes'!$A$2:$A$10,1,FALSE)=LEFT(B3,2),"Yes","Error"),"No") -> No
A4: 2023 Q4 | B4: DP.2681 | C4: Rapid Response Fund for Sudden Emergencies in Northeast Nigeria | D4: MOVEMENT, EMERGENCY AND POST-CRISIS MIGRATION MANAGEMENT | E4: Nigeria | G4: 4500359162 | H4: Entity Grants | I4: CONCERN FOR WOMEN AND CHILDREN | J4: Nigeria | K4: 57366 | L4: 61399.69 | M4: =IFERROR(IF(VLOOKUP(LEFT(B4,2),'Humanitarian codes'!$A$2:$A$10,1,FALSE)=LEFT(B4,2),"Yes","Error"),"No") -> Yes
A5: 2023 Q4 | B5: RP.0122 | C5: Restoring Our Future Activity | D5: LAND, PROPERTY AND REPARATION PROGRAMMES | E5: Colombia | G5: 4500360132 | H5: Entity Grants | I5: CORPORACION MUSEO LA TERTULIA | J5: Colombia | K5: 91329 | L5: 97751.7 | M5: =IFERROR(IF(VLOOKUP(LEFT(B5,2),'Humanitarian codes'!$A$2:$A$10,1,FALSE)=LEFT(B5,2),"Yes","Error"),"No") -> No
A6: 2023 Q4 | B6: DP.2659 | C6: Provision of Humanitarian Coordination, Shelter and Settlements, Water, Sanitation and Hygiene (WASH), Multi-Purpose Cash Assistance (MPCA), Health and Protection Assistance for Crisis-Affected Populations in Ethiopia | D6: MOVEMENT, EMERGENCY AND POST-CRISIS MIGRATION MANAGEMENT | E6: Ethiopia | G6: 4500358307 | H6: Entity Grants | I6: Afro Ethiopia Integrated Dev't | J6: Ethiopia | K6: 101100 | L6: 108209.87 | M6: =IFERROR(IF(VLOOKUP(LEFT(B6,2),'Humanitarian codes'!$A$2:$A$10,1,FALSE)=LEFT(B6,2),"Yes","Error"),"No") -> Yes
A7: 2023 Q4 | B7: PX.0419 | C7: Robust Interventions to Combat Human Trafficking in Mexico | D7: REGULATING MIGRATION | E7: Mexico | G7: 4500376188 | H7: Entity Grants | I7: JOSE MARIA VILASECA A.C. | J7: Mexico | K7: 117503 | L7: 125765.47 | M7: =IFERROR(IF(VLOOKUP(LEFT(B7,2),'Humanitarian codes'!$A$2:$A$10,1,FALSE)=LEFT(B7,2),"Yes","Error"),"No") -> No
A8: 2023 Q4 | B8: DP.2659 | C8: Provision of Humanitarian Coordination, Shelter and Settlements, Water, Sanitation and Hygiene (WASH), Multi-Purpose Cash Assistance (MPCA), Health and Protection Assistance for Crisis-Affected Populations in Ethiopia | D8: MOVEMENT, EMERGENCY AND POST-CRISIS MIGRATION MANAGEMENT | E8: Ethiopia | G8: 4500371516 | H8: Entity Grants | I8: Community in Action Against Poverty | J8: Ethiopia | K8: 130213 | L8: 139370 | M8: =IFERROR(IF(VLOOKUP(LEFT(B8,2),'Humanitarian codes'!$A$2:$A$10,1,FALSE)=LEFT(B8,2),"Yes","Error"),"No") -> Yes
A9: 2023 Q4 | B9: DP.2659 | C9: Provision of Humanitarian Coordination, Shelter and Settlements, Water, Sanitation and Hygiene (WASH), Multi-Purpose Cash Assistance (MPCA), Health and Protection Assistance for Crisis-Affected Populations in Ethiopia | D9: MOVEMENT, EMERGENCY AND POST-CRISIS MIGRATION MANAGEMENT | E9: Ethiopia | G9: 4500371470 | H9: Entity Grants | I9: Organization for Social Services He | J9: Ethiopia | K9: 145087 | L9: 155290 | M9: =IFERROR(IF(VLOOKUP(LEFT(B9,2),'Humanitarian codes'!$A$2:$A$10,1,FALSE)=LEFT(B9,2),"Yes","Error"),"No") -> Yes
A10: 2023 Q4 | B10: CC.0072 | C10: Enhancing Humanitarian Assistance to Populations Affected by Conflict and Natural Hazards in Central and Northern Mali | D10: MOVEMENT, EMERGENCY AND POST-CRISIS MIGRATION MANAGEMENT | E10: Mali | G10: 4500359121 | H10: Implementing Partner | I10: DIRECTION NAT.DEV. SOC | J10: Mali | K10: 133352 | L10: 142729.49 | M10: =IFERROR(IF(VLOOKUP(LEFT(B10,2),'Humanitarian codes'!$A$2:$A$10,1,FALSE)=LEFT(B10,2),"Yes","Error"),"No") -> Yes
A11: 2023 Q4 | B11: CD.0066 | C11: Scholarships for Educational Opportunities | D11: MIGRATION AND DEVELOPMENT | E11: El Salvador | G11: 4500354713 | H11: Implementing Partner | I11: Universidad Centroamericana Jose Si | J11: El Salvador | K11: 64253 | L11: 68771.8 | M11: =IFERROR(IF(VLOOKUP(LEFT(B11,2),'Humanitarian codes'!$A$2:$A$10,1,FALSE)=LEFT(B11,2),"Yes","Error"),"No") -> No
A12: 2023 Q4 | B12: CD.0071 | C12: SME Boost: Economic Integration of Internally Displaced People and Business Recovery (via IOM to Mitigate the COVID-19 Crisis) | D12: MIGRATION AND DEVELOPMENT | E12: Ukraine | G12: 4500365181 | H12: Implementing Partner | I12: LVIVSKA TORHOVO | J12: Ukraine | K12: 20245 | L12: 21669.05 | M12: =IFERROR(IF(VLOOKUP(LEFT(B12,2),'Humanitarian codes'!$A$2:$A$10,1,FALSE)=LEFT(B12,2),"Yes","Error"),"No") -> No
A13: 2023 Q4 | B13: CD.0074 | C13: Regional Migration and Development Program Contributing Toward the Sida 2021-2025 Regional LAC Strategy | D13: MIGRATION AND DEVELOPMENT | E13: Dominican Rep. | G13: 4500353207 | H13: Implementing Partner | I13: Fundebmuni | J13: Dominican Rep. | K13: 18195 | L13: 19474.2 | M13: =IFERROR(IF(VLOOKUP(LEFT(B13,2),'Humanitarian codes'!$A$2:$A$10,1,FALSE)=LEFT(B13,2),"Yes","Error"),"No") -> No
... A337: 2023 Q4 | B337: TK.0042 | C337: Harnessing Inclusive Global Alliances for Diaspora Engagement | D337: MIGRATION AND DEVELOPMENT | E337: Switzerland | G337: 4500364329 | H337: Implementing Partner | I337: Migration Youth and Children | J337: United Kingdom | K337: 7431 | L337: 7953.34 | M337: =IFERROR(IF(VLOOKUP(LEFT(B337,2),'Humanitarian codes'!$A$2:$A$10,1,FALSE)=LEFT(B337,2),"Yes","Error"),"No") -> No
A338: 2023 Q3 | B338: PX.0327 | C338: Protection of Vulnerable Migrants with Special Emphasis on Empowering Women in the Context of Migration in Central Asia | D338: REGULATING MIGRATION | E338: Kazakhstan | F338: grant support "protection of vulnerable migrants with emphasis on empowering women in the context of migration in Central Asia" fina ncially supported by the Ministry of Affairs of the Kingdom of Norway | G338: 4500336274 | H338: Entity Grant | I338: Kaysar | J338: Kazakhstan | K338: 9948 | L338: 9948 | M338: =IFERROR(IF(VLOOKUP(LEFT(B338,2),'Humanitarian codes'!$A$2:$A$10,1,FALSE)=LEFT(B338,2),"Yes","Error"),"No") -> No
A339: 2023 Q3 | B339: PX.0327 | C339: Protection of Vulnerable Migrants with Special Emphasis on Empowering Women in the Context of Migration in Central Asia | D339: REGULATING MIGRATION | E339: Kazakhstan | F339: grant support "protection of vulnerable migrants with emphasis on empowering women in the context of migration in Central Asia" fina ncially supported by the Ministry of Affairs of the Kingdom of Norway | G339: 4500336276 | H339: Entity Grant | I339: NGO Rodnik Almaty | J339: Kazakhstan | K339: 9948 | L339: 9948 | M339: =IFERROR(IF(VLOOKUP(LEFT(B339,2),'Humanitarian codes'!$A$2:$A$10,1,FALSE)=LEFT(B339,2),"Yes","Error"),"No") -> No
A340: 2023 Q3 | B340: CS.1128 | C340: Weaving Lives and Hope Activity (WLH) | D340: MOVEMENT, EMERGENCY AND POST-CRISIS MIGRATION MANAGEMENT | E340: Colombia | F340: GRANT WLH - WLH-002-059 - 12629243 FUNDACION GAITEROS DE SAN JACINTO LANDERO VIVE TOTAL VALUE: COP 150.000.000 IOM CONTRIB: COP 127.500.000 FUN CONTRIB: COP 22.500.000 | G340: 4500326202 | H340: Entity Grants | I340: FUNDACION GAITEROS DE SAN JACINTO - | J340: Colombia | K340: 30902 | L340: 30902 | M340: =IFERROR(IF(VLOOKUP(LEFT(B340,2),'Humanitarian codes'!$A$2:$A$10,1,FALSE)=LEFT(B340,2),"Yes","Error"),"No") -> No
A341: 2023 Q3 | B341: CS.1128 | C341: Weaving Lives and Hope Activity (WLH) | D341: MOVEMENT, EMERGENCY AND POST-CRISIS MIGRATION MANAGEMENT | E341: Colombia | F341: GRANT WLH-002-070 DE 2023 12600453 FUNDACION PARA LA RECONCILIACION TOTAL VALUE: COP 345.023.923 IOM CONTRIB: COP 285.815.000 FUN CONTRIB: COP 59.208.923 | G341: 4500328131 | H341: Entity Grants | I341: FUNDACION PARA LA RECONCILIACION | J341: Colombia | K341: 69272 | L341: 69272 | M341: =IFERROR(IF(VLOOKUP(LEFT(B341,2),'Humanitarian codes'!$A$2:$A$10,1,FALSE)=LEFT(B341,2),"Yes","Error"),"No") -> No
A342: 2023 Q3 | B342: CS.1128 | C342: Weaving Lives and Hope Activity (WLH) | D342: MOVEMENT, EMERGENCY AND POST-CRISIS MIGRATION MANAGEMENT | E342: Colombia | F342: Grants Recipients - National CSOs | G342: 4500328576 | H342: Entity Grants | I342: CORPORACION ECOSS | J342: Colombia | K342: 36355 | L342: 36355 | M342: =IFERROR(IF(VLOOKUP(LEFT(B342,2),'Humanitarian codes'!$A$2:$A$10,1,FALSE)=LEFT(B342,2),"Yes","Error"),"No") -> No
A343: 2023 Q3 | B343: CS.1128 | C343: Weaving Lives and Hope Activity (WLH) | D343: MOVEMENT, EMERGENCY AND POST-CRISIS MIGRATION MANAGEMENT | E343: Colombia | F343: Grants Recipients - National CSOs | G343: 4500328579 | H343: Entity Grants | I343: CORFOARTE CORPORACION FOLCLORICA | J343: Colombia | K343: 72710 | L343: 72710 | M343: =IFERROR(IF(VLOOKUP(LEFT(B343,2),'Humanitarian codes'!$A$2:$A$10,1,FALSE)=LEFT(B343,2),"Yes","Error"),"No") -> No
A344: 2023 Q3 | B344: CS.1128 | C344: Weaving Lives and Hope Activity (WLH) | D344: MOVEMENT, EMERGENCY AND POST-CRISIS MIGRATION MANAGEMENT | E344: Colombia | F344: Grants Recipients - National CSOs | G344: 4500328580 | H344: Entity Grants | I344: HOSPITAL NUESTRA SEÑORA DEL CARMEN | J344: Colombia | K344: 48064 | L344: 48064 | M344: =IFERROR(IF(VLOOKUP(LEFT(B344,2),'Humanitarian codes'!$A$2:$A$10,1,FALSE)=LEFT(B344,2),"Yes","Error"),"No") -> No
A345: 2023 Q3 | B345: CS.1128 | C345: Weaving Lives and Hope Activity (WLH) | D345: MOVEMENT, EMERGENCY AND POST-CRISIS MIGRATION MANAGEMENT | E345: Colombia | F345: Grants Recipients - National CSOs | G345: 4500328583 | H345: Entity Grants | I345: APROACA ASOCIACION DE PRODUCTORES | J345: Colombia | K345: 72404 | L345: 72404 | M345: =IFERROR(IF(VLOOKUP(LEFT(B345,2),'Humanitarian codes'!$A$2:$A$10,1,FALSE)=LEFT(B345,2),"Yes","Error"),"No") -> No
A346: 2023 Q3 | B346: CS.1128 | C346: Weaving Lives and Hope Activity (WLH) | D346: MOVEMENT, EMERGENCY AND POST-CRISIS MIGRATION MANAGEMENT | E346: Colombia | F346: GRANT WLH- 002-082 - 12622642 ESE HOSPITAL SAN JUAN DE DIOS TOTAL VALUE: COP 369.500.000 IOM CONTRIB: COP 300.000.000 FUN CONTRIB: COP 69.500.000 | G346: 4500328880 | H346: Entity Grants | I346: ESE HOSPITAL SAN JUAN DE DIOS | J346: Colombia | K346: 72710 | L346: 72710 | M346: =IFERROR(IF(VLOOKUP(LEFT(B346,2),'Humanitarian codes'!$A$2:$A$10,1,FALSE)=LEFT(B346,2),"Yes","Error"),"No") -> No
A347: 2023 Q3 | B347: CS.1128 | C347: Weaving Lives and Hope Activity (WLH) | D347: MOVEMENT, EMERGENCY AND POST-CRISIS MIGRATION MANAGEMENT | E347: Colombia | F347: GRANT WLH- 002-071- 12612600 FUNDACION POLIEDRO TOTAL VALUE: COP 370.000.000 IOM CONTRIB: COP 300.000.000 FUN CONTRIB: COP 70.000.000 | G347: 4500328891 | H347: Entity Grants | I347: FUNDACION POLIEDRO | J347: Colombia | K347: 72710 | L347: 72710 | M347: =IFERROR(IF(VLOOKUP(LEFT(B347,2),'Humanitarian codes'!$A$2:$A$10,1,FALSE)=LEFT(B347,2),"Yes","Error"),"No") -> No
A348: 2023 Q3 | B348: CS.1128 | C348: Weaving Lives and Hope Activity (WLH) | D348: MOVEMENT, EMERGENCY AND POST-CRISIS MIGRATION MANAGEMENT | E348: Colombia | F348: GRANT WLH- 002-072 12601016 UNIVERSIDAD TECNOLOGICA DE BOLIVAR TOTAL VALUE: COP 293.249.528 IOM CONTRIB: COP 230.701.630 FUN CONTRIB: COP 62.547.898 | G348: 4500328914 | H348: Entity Grants | I348: UNIVERSIDAD TECNOLOGICA DE BOLIVAR | J348: Colombia | K348: 55914 | L348: 55914 | M348: =IFERROR(IF(VLOOKUP(LEFT(B348,2),'Humanitarian codes'!$A$2:$A$10,1,FALSE)=LEFT(B348,2),"Yes","Error"),"No") -> No
A349: 2023 Q3 | B349: CS.1128 | C349: Weaving Lives and Hope Activity (WLH) | D349: MOVEMENT, EMERGENCY AND POST-CRISIS MIGRATION MANAGEMENT | E349: Colombia | F349: GRANT WLH-002-073 DE 2023 12629290 ASOCIACION CAFES ESPECIALES LAS INMMENSAS DEL CAUCA TOTAL VALUE: COP 187.510.000 IOM CONTRIB: COP 160.060.000 ASOCIACION CAFE:COP 27.450.000 | G349: 4500330709 | H349: Entity Grants | I349: ASOCIACION CAFES ESPECIALES LAS INM | J349: Colombia | K349: 38793 | L349: 38793 | M349: =IFERROR(IF(VLOOKUP(LEFT(B349,2),'Humanitarian codes'!$A$2:$A$10,1,FALSE)=LEFT(B349,2),"Yes","Error"),"No") -> No
... A672: 2023 Q3 | B672: PE.0031 | C672: Supporting the Iraqi National Efforts for an Enhanced Implementation of the National Strategies on the Prevention of Violent Extremism | D672: MOVEMENT, EMERGENCY AND POST-CRISIS MIGRATION MANAGEMENT | E672: Iraq | F672: PR#4200491093 | G672: 4500336889 | H672: Implementing Partner | I672: Soqya Foudation for Relief and deve | J672: Iraq | K672: 60000 | L672: 60000 | M672: =IFERROR(IF(VLOOKUP(LEFT(B672,2),'Humanitarian codes'!$A$2:$A$10,1,FALSE)=LEFT(B672,2),"Yes","Error"),"No") -> No
A673: 2023 Q3 | B673: PE.0031 | C673: Supporting the Iraqi National Efforts for an Enhanced Implementation of the National Strategies on the Prevention of Violent Extremism | D673: MOVEMENT, EMERGENCY AND POST-CRISIS MIGRATION MANAGEMENT | E673: Iraq | F673: 4200521536 | G673: 4500338512 | H673: Implementing Partner | I673: NAMA ORGANIZATION | J673: Iraq | K673: 30000 | L673: 30000 | M673: =IFERROR(IF(VLOOKUP(LEFT(B673,2),'Humanitarian codes'!$A$2:$A$10,1,FALSE)=LEFT(B673,2),"Yes","Error"),"No") -> No
A674: 2023 Q3 | B674: PE.0031 | C674: Supporting the Iraqi National Efforts for an Enhanced Implementation of the National Strategies on the Prevention of Violent Extremism | D674: MOVEMENT, EMERGENCY AND POST-CRISIS MIGRATION MANAGEMENT | E674: Iraq | F674: PR#4200521534 | G674: 4500338522 | H674: Implementing Partner | I674: Wasel Tasel | J674: Iraq | K674: 30000 | L674: 30000 | M674: =IFERROR(IF(VLOOKUP(LEFT(B674,2),'Humanitarian codes'!$A$2:$A$10,1,FALSE)=LEFT(B674,2),"Yes","Error"),"No") -> No
A675: 2023 Q3 | B675: PE.0031 | C675: Supporting the Iraqi National Efforts for an Enhanced Implementation of the National Strategies on the Prevention of Violent Extremism | D675: MOVEMENT, EMERGENCY AND POST-CRISIS MIGRATION MANAGEMENT | E675: Iraq | F675: PR#4200521480 | G675: 4500338525 | H675: Implementing Partner | I675: Elite Youth League | J675: Iraq | K675: 30000 | L675: 30000 | M675: =IFERROR(IF(VLOOKUP(LEFT(B675,2),'Humanitarian codes'!$A$2:$A$10,1,FALSE)=LEFT(B675,2),"Yes","Error"),"No") -> No
A676: 2023 Q3 | B676: PE.0031 | C676: Supporting the Iraqi National Efforts for an Enhanced Implementation of the National Strategies on the Prevention of Violent Extremism | D676: MOVEMENT, EMERGENCY AND POST-CRISIS MIGRATION MANAGEMENT | E676: Iraq | F676: PR#4200521650 | G676: 4500341877 | H676: Implementing Partner | I676: Human Line Foundation | J676: Iraq | K676: 30000 | L676: 30000 | M676: =IFERROR(IF(VLOOKUP(LEFT(B676,2),'Humanitarian codes'!$A$2:$A$10,1,FALSE)=LEFT(B676,2),"Yes","Error"),"No") -> No
A677: 2023 Q3 | B677: PE.0031 | C677: Supporting the Iraqi National Efforts for an Enhanced Implementation of the National Strategies on the Prevention of Violent Extremism | D677: MOVEMENT, EMERGENCY AND POST-CRISIS MIGRATION MANAGEMENT | E677: Iraq | F677: PR#4200521686 | G677: 4500343318 | H677: Implementing Partner | I677: National Institute for Human Rights | J677: Iraq | K677: 30000 | L677: 30000 | M677: =IFERROR(IF(VLOOKUP(LEFT(B677,2),'Humanitarian codes'!$A$2:$A$10,1,FALSE)=LEFT(B677,2),"Yes","Error"),"No") -> No
A678: 2023 Q3 | B678: PE.0031 | C678: Supporting the Iraqi National Efforts for an Enhanced Implementation of the National Strategies on the Prevention of Violent Extremism | D678: MOVEMENT, EMERGENCY AND POST-CRISIS MIGRATION MANAGEMENT | E678: Iraq | F678: PR#4200521663 | G678: 4500344623 | H678: Implementing Partner | I678: The Iraqi National Center for Youth | J678: Iraq | K678: 30000 | L678: 30000 | M678: =IFERROR(IF(VLOOKUP(LEFT(B678,2),'Humanitarian codes'!$A$2:$A$10,1,FALSE)=LEFT(B678,2),"Yes","Error"),"No") -> No
A679: 2023 Q3 | B679: PE.0031 | C679: Supporting the Iraqi National Efforts for an Enhanced Implementation of the National Strategies on the Prevention of Violent Extremism | D679: MOVEMENT, EMERGENCY AND POST-CRISIS MIGRATION MANAGEMENT | E679: Iraq | F679: PR#4200521630 | G679: 4500346099 | H679: Implementing Partner | I679: Book Forum Foundation | J679: Iraq | K679: 30000 | L679: 30000 | M679: =IFERROR(IF(VLOOKUP(LEFT(B679,2),'Humanitarian codes'!$A$2:$A$10,1,FALSE)=LEFT(B679,2),"Yes","Error"),"No") -> No
A680: 2023 Q3 | B680: PE.0031 | C680: Supporting the Iraqi National Efforts for an Enhanced Implementation of the National Strategies on the Prevention of Violent Extremism | D680: MOVEMENT, EMERGENCY AND POST-CRISIS MIGRATION MANAGEMENT | E680: Iraq | F680: PR#4200521732 | G680: 4500347988 | H680: Implementing Partner | I680: Democracy and Human Rights | J680: Iraq | K680: 30000 | L680: 30000 | M680: =IFERROR(IF(VLOOKUP(LEFT(B680,2),'Humanitarian codes'!$A$2:$A$10,1,FALSE)=LEFT(B680,2),"Yes","Error"),"No") -> No
A681: 2023 Q3 | B681: PE.0031 | C681: Supporting the Iraqi National Efforts for an Enhanced Implementation of the National Strategies on the Prevention of Violent Extremism | D681: MOVEMENT, EMERGENCY AND POST-CRISIS MIGRATION MANAGEMENT | E681: Iraq | F681: PR#4200521642 | G681: 4500350125 | H681: Implementing Partner | I681: Khalooha Ajmal Foundation | J681: Iraq | K681: 30000 | L681: 30000 | M681: =IFERROR(IF(VLOOKUP(LEFT(B681,2),'Humanitarian codes'!$A$2:$A$10,1,FALSE)=LEFT(B681,2),"Yes","Error"),"No") -> No
A682: 2023 Q3 | B682: PE.0031 | C682: Supporting the Iraqi National Efforts for an Enhanced Implementation of the National Strategies on the Prevention of Violent Extremism | D682: MOVEMENT, EMERGENCY AND POST-CRISIS MIGRATION MANAGEMENT | E682: Iraq | F682: PR#4200521654 | G682: 4500351578 | H682: Implementing Partner | I682: Jud Humanitarian Organization | J682: Iraq | K682: 30000 | L682: 30000 | M682: =IFERROR(IF(VLOOKUP(LEFT(B682,2),'Humanitarian codes'!$A$2:$A$10,1,FALSE)=LEFT(B682,2),"Yes","Error"),"No") -> No
A683: 2023 Q3 | B683: PX.0060 | C683: Reinforce Capacities to Identify and Provide Adequate Care to Victims of Trafficking in Tunisia | D683: REGULATING MIGRATION | E683: Tunisia | F683: UN Partnerships | G683: 4500339617 | H683: Implementing Partner | I683: Association AMAL pour la famille et | J683: Tunisia | K683: 28721 | L683: 28721 | M683: =IFERROR(IF(VLOOKUP(LEFT(B683,2),'Humanitarian codes'!$A$2:$A$10,1,FALSE)=LEFT(B683,2),"Yes","Error"),"No") -> No
A684: 2023 Q3 | B684: PX.0074 | C684: Risk Management: Sustainable Models and Practices for Effective PSEA Response | D684: REGULATING MIGRATION | E684: Philippines | F684: IP transfers – National CSOs | G684: 4500330760 | H684: Implementing Partner | I684: CONSORTIUM OF BANGSAMORO CIVIL SOCI | J684: Philippines | K684: 1247 | L684: 1247 | M684: =IFERROR(IF(VLOOKUP(LEFT(B684,2),'Humanitarian codes'!$A$2:$A$10,1,FALSE)=LEFT(B684,2),"Yes","Error"),"No") -> No
A685: 2023 Q3 | B685: PX.0305 | C685: Migration Resource Centers in Guatemala | D685: REGULATING MIGRATION | E685: Guatemala | F685: MRC PROJECT PR 4200491588 Implementing partner to provide information and counseling services for young people | G685: 4500339010 | H685: Implementing Partner | I685: IGLESIA CATOLICA ARQUIDIOCESIS | J685: Guatemala | K685: 38192 | L685: 38192 | M685: =IFERROR(IF(VLOOKUP(LEFT(B685,2),'Humanitarian codes'!$A$2:$A$10,1,FALSE)=LEFT(B685,2),"Yes","Error"),"No") -> No
...

Sheet 2024
A1: Year and Quarter | B1: Project ID | C1: Project Type | D1: Project Title | E1: Purchasing Country | F1: PO Number | G1: PO Type per Report | H1: Vendor Counterpart Name | I1: Vendor Country | J1: USD Value (per PO and Project) / Sum of Value in USD (Charged to Project) | K1: USD Value (total per PO) / Total Value in USD / Total PO Value in USD | L1: Humanitarian
A2: 2024 Q4 | B2: CD.0066 | C2: MIGRATION AND DEVELOPMENT | D2: Scholarships for Educational Opportunities | E2: El Salvador | F2: 4500462013 | G2: Implementing Partner | H2: FUNDEPLAST | I2: El Salvador | J2: 517800 | K2: 517800 | L2: =IFERROR(IF(VLOOKUP(LEFT(B2,2),'Humanitarian codes'!$A$2:$A$10,1,FALSE)=LEFT(B2,2),"Yes","Error"),"No") -> No
A3: 2024 Q4 | B3: CD.0099 | C3: MIGRATION AND DEVELOPMENT | D3: Consolidating the Reintegration Achievements of Senegalese Returned Migrants through Integrated Support to Micro and Small Enterprises (Phase II) | E3: Senegal | F3: 4500472988 | G3: Implementing Partner | H3: VOLONTARIATO INTERNAZIONALE PER LO | I3: Senegal | J3: 114794.92 | K3: 114794.92 | L3: =IFERROR(IF(VLOOKUP(LEFT(B3,2),'Humanitarian codes'!$A$2:$A$10,1,FALSE)=LEFT(B3,2),"Yes","Error"),"No") -> No
A4: 2024 Q4 | B4: CD.0105 | C4: MIGRATION AND DEVELOPMENT | D4: Business Development Initiatives - IDEE Youth | E4: Niger | F4: 4500456751 | G4: Implementing Partner | H4: CIPMEN | I4: Niger | J4: 171348.24 | K4: 171348.24 | L4: =IFERROR(IF(VLOOKUP(LEFT(B4,2),'Humanitarian codes'!$A$2:$A$10,1,FALSE)=LEFT(B4,2),"Yes","Error"),"No") -> No
A5: 2024 Q4 | B5: CD.0105 | C5: MIGRATION AND DEVELOPMENT | D5: Business Development Initiatives - IDEE Youth | E5: Niger | F5: 4500464369 | G5: Implementing Partner | H5: ASSOCIATION BOUNKASSAR | I5: Niger | J5: 170173.2 | K5: 170173.2 | L5: =IFERROR(IF(VLOOKUP(LEFT(B5,2),'Humanitarian codes'!$A$2:$A$10,1,FALSE)=LEFT(B5,2),"Yes","Error"),"No") -> No
A6: 2024 Q4 | B6: CD.0114 | C6: MIGRATION AND DEVELOPMENT | D6: Favorable Opportunity For Self-Advancement of Today’s Youth Plus Activity (FORSATY Plus) | E6: Morocco | F6: 4500465586 | G6: Implementing Partner | H6: Association Atil | I6: Morocco | J6: 101483.66 | K6: 101483.66 | L6: =IFERROR(IF(VLOOKUP(LEFT(B6,2),'Humanitarian codes'!$A$2:$A$10,1,FALSE)=LEFT(B6,2),"Yes","Error"),"No") -> No
A7: 2024 Q4 | B7: CD.0114 | C7: MIGRATION AND DEVELOPMENT | D7: Favorable Opportunity For Self-Advancement of Today’s Youth Plus Activity (FORSATY Plus) | E7: Morocco | F7: 4500472407 | G7: Implementing Partner | H7: Raouabit Assadaka | I7: Morocco | J7: 119952.03 | K7: 119952.03 | L7: =IFERROR(IF(VLOOKUP(LEFT(B7,2),'Humanitarian codes'!$A$2:$A$10,1,FALSE)=LEFT(B7,2),"Yes","Error"),"No") -> No
A8: 2024 Q4 | B8: CD.0114 | C8: MIGRATION AND DEVELOPMENT | D8: Favorable Opportunity For Self-Advancement of Today’s Youth Plus Activity (FORSATY Plus) | E8: Morocco | F8: 4500476049 | G8: Implementing Partner | H8: Association UNFM Tetouan | I8: Morocco | J8: 149940.02 | K8: 149940.02 | L8: =IFERROR(IF(VLOOKUP(LEFT(B8,2),'Humanitarian codes'!$A$2:$A$10,1,FALSE)=LEFT(B8,2),"Yes","Error"),"No") -> No
A9: 2024 Q4 | B9: CS.1139 | C9: MOVEMENT, EMERGENCY AND POST-CRISIS MIGRATION MANAGEMENT | D9: UN Joint Program for Strengthening Inclusive Social Cohesion and Economic Resilience in Abyei Area, Sudan | E9: Sudan | F9: 4500457997 | G9: Implementing Partner | H9: Hope and Friendship for Development | I9: Sudan | J9: 92247 | K9: 92247 | L9: =IFERROR(IF(VLOOKUP(LEFT(B9,2),'Humanitarian codes'!$A$2:$A$10,1,FALSE)=LEFT(B9,2),"Yes","Error"),"No") -> No
A10: 2024 Q4 | B10: CD.0114 | C10: MIGRATION AND DEVELOPMENT | D10: Favorable Opportunity For Self-Advancement of Today’s Youth Plus Activity (FORSATY Plus) | E10: Morocco | F10: 4500476456 | G10: Implementing Partner | H10: Association Chifae pour | I10: Morocco | J10: 159936.03 | K10: 159936.03 | L10: =IFERROR(IF(VLOOKUP(LEFT(B10,2),'Humanitarian codes'!$A$2:$A$10,1,FALSE)=LEFT(B10,2),"Yes","Error"),"No") -> No
A11: 2024 Q4 | B11: CS.1202 | C11: MOVEMENT, EMERGENCY AND POST-CRISIS MIGRATION MANAGEMENT | D11: Addressing Human Security through Integrated Support for the Most Vulnerable and Crisis-Affected Communities in South Kordofan | E11: Sudan | F11: 4500475401 | G11: Implementing Partner | H11: Alsalam Organization for Rehabilita | I11: Sudan | J11: 133500 | K11: 133500 | L11: =IFERROR(IF(VLOOKUP(LEFT(B11,2),'Humanitarian codes'!$A$2:$A$10,1,FALSE)=LEFT(B11,2),"Yes","Error"),"No") -> No
A12: 2024 Q4 | B12: CS.1203 | C12: MOVEMENT, EMERGENCY AND POST-CRISIS MIGRATION MANAGEMENT | D12: Coastal States Stability Mechanism (CSSM) | E12: Ghana | F12: 4500466886 | G12: Implementing Partner | H12: NORTHERN REGIONAL PEACE COUNCIL | I12: Ghana | J12: 26644.65 | K12: 53289.31 | L12: =IFERROR(IF(VLOOKUP(LEFT(B12,2),'Humanitarian codes'!$A$2:$A$10,1,FALSE)=LEFT(B12,2),"Yes","Error"),"No") -> No
A13: 2024 Q4 | B13: CS.1203 | C13: MOVEMENT, EMERGENCY AND POST-CRISIS MIGRATION MANAGEMENT | D13: Coastal States Stability Mechanism (CSSM) | E13: Ghana | F13: 4500470999 | G13: Implementing Partner | H13: CSD REFORM | I13: Ghana | J13: 27647.95 | K13: 55295.91 | L13: =IFERROR(IF(VLOOKUP(LEFT(B13,2),'Humanitarian codes'!$A$2:$A$10,1,FALSE)=LEFT(B13,2),"Yes","Error"),"No") -> No
... A465: 2024 Q3 | B465: DP.2470 | C465: IOM Flash Appeal for Ukraine and Neighbouring Countries 2022 - Norway | D465: MOVEMENT, EMERGENCY AND POST-CRISIS MIGRATION MANAGEMENT | E465: Ukraine | F465: 4500439194 | G465: Implementing Partner | H465: NGO ROAD TO LIFE | I465: Ukraine | J465: 39278.67 | K465: 68763.01 | L465: =IFERROR(IF(VLOOKUP(LEFT(B465,2),'Humanitarian codes'!$A$2:$A$10,1,FALSE)=LEFT(B465,2),"Yes","Error"),"No") -> Yes
A466: 2024 Q3 | B466: CS.1223 | C466: Support Program for the Prevention of Conflicts and Violent Extremism in the Border Areas of Togo, Benin and Burkina Faso, Phase 2 | D466: MOVEMENT, EMERGENCY AND POST-CRISIS MIGRATION MANAGEMENT | F466: 4500438130 | G466: Implementing Partner | H466: ASSOCIATION LES CHAMPIONS DE | I466: Benin | J466: 106499.72 | K466: 106499.72 | L466: =IFERROR(IF(VLOOKUP(LEFT(B466,2),'Humanitarian codes'!$A$2:$A$10,1,FALSE)=LEFT(B466,2),"Yes","Error"),"No") -> No
A467: 2024 Q3 | B467: CS.1197 | C467: Strengthened Access to Education and Livelihoods and Enhanced Reintegration and Community Cohesion in Areas Affected by Displacement and Returns | D467: MOVEMENT, EMERGENCY AND POST-CRISIS MIGRATION MANAGEMENT | E467: South Sudan | F467: 4500434880 | G467: Implementing Partner | H467: UNICEF | I467: Denmark | J467: 1634925.4 | K467: 1634925.4 | L467: =IFERROR(IF(VLOOKUP(LEFT(B467,2),'Humanitarian codes'!$A$2:$A$10,1,FALSE)=LEFT(B467,2),"Yes","Error"),"No") -> No
A468: 2024 Q3 | B468: CS.1216 | C468: Support Program for the Prevention of Conflicts and Violent Extremism in the Border Areas of Togo, Benin and Burkina Faso, Phase 2 | D468: MOVEMENT, EMERGENCY AND POST-CRISIS MIGRATION MANAGEMENT | F468: 4500436069 | G468: Implementing Partner | H468: ANPE | I468: Togo | J468: 149972.05 | K468: 149972.05 | L468: =IFERROR(IF(VLOOKUP(LEFT(B468,2),'Humanitarian codes'!$A$2:$A$10,1,FALSE)=LEFT(B468,2),"Yes","Error"),"No") -> No
A469: 2024 Q3 | B469: CS.1197 | C469: Strengthened Access to Education and Livelihoods and Enhanced Reintegration and Community Cohesion in Areas Affected by Displacement and Returns | D469: MOVEMENT, EMERGENCY AND POST-CRISIS MIGRATION MANAGEMENT | E469: South Sudan | F469: 4500434881 | G469: Implementing Partner | H469: World Food Programme-SS | I469: South Sudan | J469: 2934045.2 | K469: 2934045.2 | L469: =IFERROR(IF(VLOOKUP(LEFT(B469,2),'Humanitarian codes'!$A$2:$A$10,1,FALSE)=LEFT(B469,2),"Yes","Error"),"No") -> No
A470: 2024 Q3 | B470: CS.1175 | C470: EU Support to Migration Management in Serbia – Improving Reception Capacity, Protection Services and Access to Education III | D470: MOVEMENT, EMERGENCY AND POST-CRISIS MIGRATION MANAGEMENT | E470: Serbia | F470: 4500447367 | G470: Implementing Partner | H470: OS Sremski front | I470: Serbia | J470: 4434.59 | K470: 4434.59 | L470: =IFERROR(IF(VLOOKUP(LEFT(B470,2),'Humanitarian codes'!$A$2:$A$10,1,FALSE)=LEFT(B470,2),"Yes","Error"),"No") -> No
A471: 2024 Q3 | B471: CS.1214 | C471: Livelihood Enhancement Program for Refugees, Migrants, Mauritanian Returnees, and Host Communities in Hodh Chargui | D471: MOVEMENT, EMERGENCY AND POST-CRISIS MIGRATION MANAGEMENT | E471: Mauritania | F471: 4500445007 | G471: Implementing Partner | H471: Delegation Regional Elevage Nema | I471: Mauritania | J471: 13444.53 | K471: 13444.53 | L471: =IFERROR(IF(VLOOKUP(LEFT(B471,2),'Humanitarian codes'!$A$2:$A$10,1,FALSE)=LEFT(B471,2),"Yes","Error"),"No") -> No
A472: 2024 Q3 | B472: CS.1216 | C472: Support Program for the Prevention of Conflicts and Violent Extremism in the Border Areas of Togo, Benin and Burkina Faso, Phase 2 | D472: MOVEMENT, EMERGENCY AND POST-CRISIS MIGRATION MANAGEMENT | F472: 4500433823 | G472: Implementing Partner | H472: Reseau Femmes et Developpement des | I472: Togo | J472: 145890.37 | K472: 145890.37 | L472: =IFERROR(IF(VLOOKUP(LEFT(B472,2),'Humanitarian codes'!$A$2:$A$10,1,FALSE)=LEFT(B472,2),"Yes","Error"),"No") -> No
A473: 2024 Q3 | B473: DP.2470 | C473: IOM Flash Appeal for Ukraine and Neighbouring Countries 2022 - Norway | D473: MOVEMENT, EMERGENCY AND POST-CRISIS MIGRATION MANAGEMENT | E473: Ukraine | F473: 4500439423 | G473: Implementing Partner | H473: NGO Caritas I-F Char Foundation | I473: Ukraine | J473: 43529.36 | K473: 55821.89 | L473: =IFERROR(IF(VLOOKUP(LEFT(B473,2),'Humanitarian codes'!$A$2:$A$10,1,FALSE)=LEFT(B473,2),"Yes","Error"),"No") -> Yes
A474: 2024 Q3 | B474: DP.2470 | C474: IOM Flash Appeal for Ukraine and Neighbouring Countries 2022 - Norway | D474: MOVEMENT, EMERGENCY AND POST-CRISIS MIGRATION MANAGEMENT | E474: Ukraine | F474: 4500439428 | G474: Implementing Partner | H474: NGO FAIITH HOPE LOVE - ODESA | I474: Ukraine | J474: 42566.27 | K474: 53792.78 | L474: =IFERROR(IF(VLOOKUP(LEFT(B474,2),'Humanitarian codes'!$A$2:$A$10,1,FALSE)=LEFT(B474,2),"Yes","Error"),"No") -> Yes
A475: 2024 Q3 | B475: DP.2470 | C475: IOM Flash Appeal for Ukraine and Neighbouring Countries 2022 - Norway | D475: MOVEMENT, EMERGENCY AND POST-CRISIS MIGRATION MANAGEMENT | E475: Ukraine | F475: 4500439430 | G475: Implementing Partner | H475: NGO Liubystok | I475: Ukraine | J475: 47287.03 | K475: 50565.1 | L475: =IFERROR(IF(VLOOKUP(LEFT(B475,2),'Humanitarian codes'!$A$2:$A$10,1,FALSE)=LEFT(B475,2),"Yes","Error"),"No") -> Yes
A476: 2024 Q3 | B476: DP.2470 | C476: IOM Flash Appeal for Ukraine and Neighbouring Countries 2022 - Norway | D476: MOVEMENT, EMERGENCY AND POST-CRISIS MIGRATION MANAGEMENT | E476: Ukraine | F476: 4500439425 | G476: Implementing Partner | H476: NGO Spring of Hope. Ukraine | I476: Ukraine | J476: 53000 | K476: 64975.9 | L476: =IFERROR(IF(VLOOKUP(LEFT(B476,2),'Humanitarian codes'!$A$2:$A$10,1,FALSE)=LEFT(B476,2),"Yes","Error"),"No") -> Yes
A477: 2024 Q3 | B477: CS.1228 | C477: Coastal States Stability Mechanism (CSSM) | D477: MOVEMENT, EMERGENCY AND POST-CRISIS MIGRATION MANAGEMENT | E477: Ghana | F477: 4500435849 | G477: Implementing Partner | H477: North East Regional House of Chiefs | I477: Ghana | J477: 25586.73 | K477: 25586.73 | L477: =IFERROR(IF(VLOOKUP(LEFT(B477,2),'Humanitarian codes'!$A$2:$A$10,1,FALSE)=LEFT(B477,2),"Yes","Error"),"No") -> No
A478: 2024 Q3 | B478: CS.1263 | C478: Energetic Transition and Territorial Peace-Building in Colombia. Strengthening Community Organizations in PDET and ZOMAC Territories | D478: MOVEMENT, EMERGENCY AND POST-CRISIS MIGRATION MANAGEMENT | E478: Colombia | F478: 4500436694 | G478: Implementing Partner | H478: CORPORACION COLOMBIANA RECREANDO I | I478: Colombia | J478: 72123.53 | K478: 1442470.7 | L478: =IFERROR(IF(VLOOKUP(LEFT(B478,2),'Humanitarian codes'!$A$2:$A$10,1,FALSE)=LEFT(B478,2),"Yes","Error"),"No") -> No
A479: 2024 Q3 | B479: CS.1252 | C479: Energetic Transition and Territorial Peace-Building in Colombia. Strengthening Community Organizations in PDET and ZOMAC Territories | D479: MOVEMENT, EMERGENCY AND POST-CRISIS MIGRATION MANAGEMENT | E479: Colombia | F479: 4500436694 | G479: Implementing Partner | H479: CORPORACION COLOMBIANA RECREANDO I | I479: Colombia | J479: 1370347.1 | K479: 1442470.7 | L479: =IFERROR(IF(VLOOKUP(LEFT(B479,2),'Humanitarian codes'!$A$2:$A$10,1,FALSE)=LEFT(B479,2),"Yes","Error"),"No") -> No
A480: 2024 Q3 | B480: CS.1280 | C480: Prevention of Recruitment, Use and Exploitation of Children, Adolescents and Young People Phase III | D480: MOVEMENT, EMERGENCY AND POST-CRISIS MIGRATION MANAGEMENT | E480: Colombia | F480: 4500433142 | G480: Implementing Partner | H480: FUNDACION VISION DIVINA DEL MANANA | I480: Colombia | J480: 109033.49 | K480: 109033.49 | L480: =IFERROR(IF(VLOOKUP(LEFT(B480,2),'Humanitarian codes'!$A$2:$A$10,1,FALSE)=LEFT(B480,2),"Yes","Error"),"No") -> No
A481: 2024 Q3 | B481: DP.2413 | C481: Support to Displaced Afghans in Pakistan, Iran, Central Asia, and Afghanistan | D481: MOVEMENT, EMERGENCY AND POST-CRISIS MIGRATION MANAGEMENT | E481: Afghanistan | F481: 4500436404 | G481: Implementing Partner | H481: Norwegian Refugee Council NRC | I481: Afghanistan | J481: 979635.58 | K481: 979635.58 | L481: =IFERROR(IF(VLOOKUP(LEFT(B481,2),'Humanitarian codes'!$A$2:$A$10,1,FALSE)=LEFT(B481,2),"Yes","Error"),"No") -> Yes
A482: 2024 Q3 | B482: DP.2470 | C482: IOM Flash Appeal for Ukraine and Neighbouring Countries 2022 - Norway | D482: MOVEMENT, EMERGENCY AND POST-CRISIS MIGRATION MANAGEMENT | E482: Ukraine | F482: 4500439420 | G482: Implementing Partner | H482: NGO Revival of the Nation | I482: Ukraine | J482: 34204.82 | K482: 60575.9 | L482: =IFERROR(IF(VLOOKUP(LEFT(B482,2),'Humanitarian codes'!$A$2:$A$10,1,FALSE)=LEFT(B482,2),"Yes","Error"),"No") -> Yes
A483: 2024 Q3 | B483: DP.2470 | C483: IOM Flash Appeal for Ukraine and Neighbouring Countries 2022 - Norway | D483: MOVEMENT, EMERGENCY AND POST-CRISIS MIGRATION MANAGEMENT | E483: Ukraine | F483: 4500439433 | G483: Implementing Partner | H483: CLEAR PAPER | I483: Ukraine | J483: 104384.58 | K483: 111029.16 | L483: =IFERROR(IF(VLOOKUP(LEFT(B483,2),'Humanitarian codes'!$A$2:$A$10,1,FALSE)=LEFT(B483,2),"Yes","Error"),"No") -> Yes
A484: 2024 Q3 | B484: DP.2470 | C484: IOM Flash Appeal for Ukraine and Neighbouring Countries 2022 - Norway | D484: MOVEMENT, EMERGENCY AND POST-CRISIS MIGRATION MANAGEMENT | E484: Ukraine | F484: 4500440064 | G484: Implementing Partner | H484: BO STO VIDSOTKIV ZHYTTIA CHERKASY | I484: Ukraine | J484: 49709.64 | K484: 61348.19 | L484: =IFERROR(IF(VLOOKUP(LEFT(B484,2),'Humanitarian codes'!$A$2:$A$10,1,FALSE)=LEFT(B484,2),"Yes","Error"),"No") -> Yes
... A1324: 2024 Q1 | B1324: DP.2790 | C1324: Evidence-Based Protection Assistance for Populations Affected by Natural Hazards in Burundi | D1324: MOVEMENT, EMERGENCY AND POST-CRISIS MIGRATION MANAGEMENT | E1324: Burundi | F1324: 4500398162 | G1324: Implementing Partner | H1324: CROIX ROUGE DU BURUNDI | I1324: Burundi | J1324: 7179.06 | K1324: 35895.34 | L1324: =IFERROR(IF(VLOOKUP(LEFT(B1324,2),'Humanitarian codes'!$A$2:$A$10,1,FALSE)=LEFT(B1324,2),"Yes","Error"),"No") -> Yes
A1325: 2024 Q1 | B1325: DP.2805 | D1325: MOVEMENT, EMERGENCY AND POST-CRISIS MIGRATION MANAGEMENT | E1325: Moldova (Rep) | F1325: 4500398913 | G1325: Implementing Partner | H1325: AO INTERACTIUNE | I1325: Moldova (Rep) | J1325: 21339.28 | K1325: 29797.13 | L1325: =IFERROR(IF(VLOOKUP(LEFT(B1325,2),'Humanitarian codes'!$A$2:$A$10,1,FALSE)=LEFT(B1325,2),"Yes","Error"),"No") -> Yes
A1326: 2024 Q1 | B1326: DR.0060 | C1326: The Bor Flood Mitigation Project | D1326: MIGRATION AND DEVELOPMENT | E1326: South Sudan | F1326: 4500404921 | G1326: Implementing Partner | H1326: TITI FOUNDATION | I1326: South Sudan | J1326: 225000 | K1326: 225000 | L1326: =IFERROR(IF(VLOOKUP(LEFT(B1326,2),'Humanitarian codes'!$A$2:$A$10,1,FALSE)=LEFT(B1326,2),"Yes","Error"),"No") -> Yes
A1327: 2024 Q1 | B1327: DR.0062 | C1327: Strengthening National and Local Disaster Preparedness and Response Capacities in Border Areas and Transhumance Corridors in Hodh Ech Chargui Region of Mauritania. | D1327: MIGRATION AND DEVELOPMENT | E1327: Mauritania | F1327: 4500397599 | G1327: Implementing Partner | H1327: Delegation Environnement | I1327: Mauritania | J1327: 38934.95 | K1327: 38934.95 | L1327: =IFERROR(IF(VLOOKUP(LEFT(B1327,2),'Humanitarian codes'!$A$2:$A$10,1,FALSE)=LEFT(B1327,2),"Yes","Error"),"No") -> Yes
A1328: 2024 Q1 | B1328: DR.0062 | C1328: Strengthening National and Local Disaster Preparedness and Response Capacities in Border Areas and Transhumance Corridors in Hodh Ech Chargui Region of Mauritania. | D1328: MIGRATION AND DEVELOPMENT | E1328: Mauritania | F1328: 4500400581 | G1328: Implementing Partner | H1328: Delegation Regional Elevage Nema | I1328: Mauritania | J1328: 90477.26 | K1328: 90477.26 | L1328: =IFERROR(IF(VLOOKUP(LEFT(B1328,2),'Humanitarian codes'!$A$2:$A$10,1,FALSE)=LEFT(B1328,2),"Yes","Error"),"No") -> Yes
A1329: 2024 Q1 | B1329: DR.0065 | C1329: Restoring the Environment and Strengthening Resilience of Rohingya Refugees and Host Communities in Cox’s Bazar | D1329: MIGRATION AND DEVELOPMENT | E1329: Bangladesh | F1329: 4500387255 | G1329: Implementing Partner | H1329: Society for Health Extension &Dev.( | I1329: Bangladesh | J1329: 200402.38 | K1329: 200402.38 | L1329: =IFERROR(IF(VLOOKUP(LEFT(B1329,2),'Humanitarian codes'!$A$2:$A$10,1,FALSE)=LEFT(B1329,2),"Yes","Error"),"No") -> Yes
A1330: 2024 Q1 | B1330: DR.0065 | C1330: Restoring the Environment and Strengthening Resilience of Rohingya Refugees and Host Communities in Cox’s Bazar | D1330: MIGRATION AND DEVELOPMENT | E1330: Bangladesh | F1330: 4500387258 | G1330: Implementing Partner | H1330: DSK | I1330: Bangladesh | J1330: 174772.27 | K1330: 174772.27 | L1330: =IFERROR(IF(VLOOKUP(LEFT(B1330,2),'Humanitarian codes'!$A$2:$A$10,1,FALSE)=LEFT(B1330,2),"Yes","Error"),"No") -> Yes
...

Sheet Consolidated
A1: Year and Quarter | B1: Project ID | C1: Project Title | D1: Project Type | E1: Purchasing Country | F1: Purchase Order or Contract Number | G1: Title of the Purchase Order or Contract | H1: Procurement, IP or GRE? | I1: Counterpart Name | J1: Counterpart Location | K1: Value of PO/Contract per Project (USD) | L1: Humanitarian | M1: Org type
A2: 2022 | B2: DP.2413 | C2: Support to Displaced Afghans in Pakistan, Iran, Central Asia, and Afghanistan | D2: MOVEMENT, EMERGENCY AND POST-CRISIS MIGRATION MANAGEMENT | E2: Tajikistan | F2: 4500243699 | G2: Hiring of Implementing partners for provision of logistical and technical support to IOM within the project "Support to Displaced Af ghans in Pakistan, Iran, Central Asia, and Afghanistan” Reference Documents: PR No.: 4200302087 dated 04 August 2022 Pro | H2: Grant Awards | I2: NGO Femida | J2: Tajikistan | K2: 51278 | L2: Yes | M2: {=INDEX('Org List'!$A$2:$C$1005,MATCH(Consolidated!I2&Consolidated!J2,'Org List'!$A$2:$A$1005&'Org List'!$B$2:$B$1005,0),3)} -> NGOs: National
A3: 2022 | B3: DP.2413 | C3: Support to Displaced Afghans in Pakistan, Iran, Central Asia, and Afghanistan | D3: MOVEMENT, EMERGENCY AND POST-CRISIS MIGRATION MANAGEMENT | E3: Tajikistan | F3: 4500243703 | G3: Hiring of Implementing partners for provision of logistical and technical support to IOM within the project "Support to Displaced Af ghans in Pakistan, Iran, Central Asia, and Afghanistan" Reference Documents: PR No.: 4200302087 dated 04 August 2022 Pro | H3: Grant Awards | I3: Women & Society | J3: Tajikistan | K3: 26577 | L3: Yes | M3: {=INDEX('Org List'!$A$2:$C$1005,MATCH(Consolidated!I3&Consolidated!J3,'Org List'!$A$2:$A$1005&'Org List'!$B$2:$B$1005,0),3)} -> NGOs: National
A4: 2022 | B4: DP.2423 | C4: Emergency Multi-Purpose Cash Assistance to Vulnerable Households in Tonga | D4: MOVEMENT, EMERGENCY AND POST-CRISIS MIGRATION MANAGEMENT | E4: Tonga | F4: 4500197484 | G4: Interim Report | H4: Grant Awards | I4: MORDI Tonga Trust | J4: Tonga | K4: 200000 | L4: Yes | M4: {=INDEX('Org List'!$A$2:$C$1005,MATCH(Consolidated!I4&Consolidated!J4,'Org List'!$A$2:$A$1005&'Org List'!$B$2:$B$1005,0),3)} -> NGOs: National
A5: 2022 | B5: DP.2452 | C5: Lifesaving Assistance for Conflict-Affected People in Ukraine and Neighbouring Countries | D5: MOVEMENT, EMERGENCY AND POST-CRISIS MIGRATION MANAGEMENT | E5: Poland | F5: 4500220613 | G5: Implementing partner agreement as per PR 4200245571 | H5: Grant Awards | I5: Unitatem Foundation | J5: Poland | K5: 110733 | L5: Yes | M5: {=INDEX('Org List'!$A$2:$C$1005,MATCH(Consolidated!I5&Consolidated!J5,'Org List'!$A$2:$A$1005&'Org List'!$B$2:$B$1005,0),3)} -> NGOs: National
A6: 2022 | B6: DP.2452 | C6: Lifesaving Assistance for Conflict-Affected People in Ukraine and Neighbouring Countries | D6: MOVEMENT, EMERGENCY AND POST-CRISIS MIGRATION MANAGEMENT | E6: Poland | F6: 4500220641 | G6: IP - Agreement - The Central Council of Roma | H6: Grant Awards | I6: Centralna Rada Romow w Polsce | J6: Poland | K6: 165127 | L6: Yes | M6: {=INDEX('Org List'!$A$2:$C$1005,MATCH(Consolidated!I6&Consolidated!J6,'Org List'!$A$2:$A$1005&'Org List'!$B$2:$B$1005,0),3)} -> NGOs: National
A7: 2022 | B7: DP.2465 | C7: IOM Flash Appeal for Ukraine and Neighboring Countries | D7: MOVEMENT, EMERGENCY AND POST-CRISIS MIGRATION MANAGEMENT | E7: Belarus | F7: 4500267537 | G7: Grant to implementing partner | H7: Grant Awards | I7: Movement of Medical Workers | J7: Belarus | K7: 12111 | L7: Yes | M7: {=INDEX('Org List'!$A$2:$C$1005,MATCH(Consolidated!I7&Consolidated!J7,'Org List'!$A$2:$A$1005&'Org List'!$B$2:$B$1005,0),3)} -> NGOs: National
A8: 2022 | B8: DP.2465 | C8: IOM Flash Appeal for Ukraine and Neighboring Countries | D8: MOVEMENT, EMERGENCY AND POST-CRISIS MIGRATION MANAGEMENT | E8: Poland | F8: 4500220613 | G8: Implementing partner agreement as per PR 4200245571 | H8: Grant Awards | I8: Unitatem Foundation | J8: Poland | K8: 380051 | L8: Yes | M8: {=INDEX('Org List'!$A$2:$C$1005,MATCH(Consolidated!I8&Consolidated!J8,'Org List'!$A$2:$A$1005&'Org List'!$B$2:$B$1005,0),3)} -> NGOs: National
A9: 2022 | B9: DP.2470 | C9: IOM Flash Appeal for Ukraine and Neighbouring Countries 2022 - Norway | D9: MOVEMENT, EMERGENCY AND POST-CRISIS MIGRATION MANAGEMENT | E9: Poland | F9: 4500220613 | G9: Implementing partner agreement as per PR 4200245571 | H9: Grant Awards | I9: Unitatem Foundation | J9: Poland | K9: 20003 | L9: Yes | M9: {=INDEX('Org List'!$A$2:$C$1005,MATCH(Consolidated!I9&Consolidated!J9,'Org List'!$A$2:$A$1005&'Org List'!$B$2:$B$1005,0),3)} -> NGOs: National
A10: 2022 | B10: SN.0195 | C10: Shelter and Non-food Items Emergency Assistance to Affected People in Batken Region of the Kyrgyz Republic | D10: MOVEMENT, EMERGENCY AND POST-CRISIS MIGRATION MANAGEMENT | E10: Kyrgyzstan | F10: 4500266464 | G10: Grant to National Implementing Partner PF "Ulybka" to carry out NFIs distribution. Agreement 2022_NFI/02. Project code: SN.0195/ DP.2533. | H10: Grant Awards | I10: Public Fund Ulybka | J10: Kyrgyzstan | K10: 61075 | L10: Yes | M10: {=INDEX('Org List'!$A$2:$C$1005,MATCH(Consolidated!I10&Consolidated!J10,'Org List'!$A$2:$A$1005&'Org List'!$B$2:$B$1005,0),3)} -> NGOs: National
A11: 2022 | B11: SN.0195 | C11: Shelter and Non-food Items Emergency Assistance to Affected People in Batken Region of the Kyrgyz Republic | D11: MOVEMENT, EMERGENCY AND POST-CRISIS MIGRATION MANAGEMENT | E11: Kyrgyzstan | F11: 4500266466 | G11: 000000000500000132-Grants Recipients - National CSOs | H11: Grant Awards | I11: Public Foundation Blagodat | J11: Kyrgyzstan | K11: 54310 | L11: Yes | M11: {=INDEX('Org List'!$A$2:$C$1005,MATCH(Consolidated!I11&Consolidated!J11,'Org List'!$A$2:$A$1005&'Org List'!$B$2:$B$1005,0),3)} -> NGOs: National
A12: 2022 | B12: CC.0031 | C12: Supporting the Greek Authorities in Managing the National Reception System for Asylum Seekers and Vulnerable Migrants (SMS) | D12: MOVEMENT, EMERGENCY AND POST-CRISIS MIGRATION MANAGEMENT | E12: Greece | F12: 4500188007 | G12: IP for the implementation of the project ""Supporting the Greek Authorities in Managing the National Reception System for Asylum Seekers and Vulnerable Migrants (SMS 2020)" | H12: Implementing Partners | I12: DANISH REFUGEE COUNCIL | J12: Greece | K12: 4874288 | L12: Yes | M12: {=INDEX('Org List'!$A$2:$C$1005,MATCH(Consolidated!I12&Consolidated!J12,'Org List'!$A$2:$A$1005&'Org List'!$B$2:$B$1005,0),3)} -> NGOs: International
A13: 2022 | B13: CC.0031 | C13: Supporting the Greek Authorities in Managing the National Reception System for Asylum Seekers and Vulnerable Migrants (SMS) | D13: MOVEMENT, EMERGENCY AND POST-CRISIS MIGRATION MANAGEMENT | E13: Greece | F13: 4500190099 | G13: IP for the Implementation of the project "Supporting the Greek Authorities in Managing the National Reception System for Asylum Seekers and Vulnerable Migrants (SMS)" | H13: Implementing Partners | I13: ARSIS | J13: Greece | K13: 2118166 | L13: Yes | M13: {=INDEX('Org List'!$A$2:$C$1005,MATCH(Consolidated!I13&Consolidated!J13,'Org List'!$A$2:$A$1005&'Org List'!$B$2:$B$1005,0),3)} -> NGOs: National
... A904: 2022 | B904: SN.0189 | C904: Humanitarian Shelter Assistance for Vulnerable Populations Affected by Conflict in Ituri and North Kivu, Democratic Republic of the Congo (DRC) | D904: MOVEMENT, EMERGENCY AND POST-CRISIS MIGRATION MANAGEMENT | E904: Congo (Dem Rep) | F904: 4500256245 | G904: Transfer_Payment for implementing partner ADSSE for shelter assistance in Ituri province | H904: Implementing Partners | I904: ADSSE(ASS.POUR LE DEVELOPPEMENT SOC | J904: Congo (Dem Rep) | K904: 299874 | L904: Yes | M904: {=INDEX('Org List'!$A$2:$C$1005,MATCH(Consolidated!I904&Consolidated!J904,'Org List'!$A$2:$A$1005&'Org List'!$B$2:$B$1005,0),3)} -> NGOs: National
A905: 2023 Q4 | B905: DP.2659 | C905: Provision of Humanitarian Coordination, Shelter and Settlements, Water, Sanitation and Hygiene (WASH), Multi-Purpose Cash Assistance (MPCA), Health and Protection Assistance for Crisis-Affected Populations in Ethiopia | D905: MOVEMENT, EMERGENCY AND POST-CRISIS MIGRATION MANAGEMENT | E905: Ethiopia | F905: 4500364246 | H905: Entity Grants | I905: Tigray Youth Empowerment Solutions | J905: Ethiopia | K905: 29267 | L905: Yes | M905: {=INDEX('Org List'!$A$2:$C$1005,MATCH(Consolidated!I905&Consolidated!J905,'Org List'!$A$2:$A$1005&'Org List'!$B$2:$B$1005,0),3)} -> NGOs: Local
A906: 2023 Q4 | B906: DP.2681 | C906: Rapid Response Fund for Sudden Emergencies in Northeast Nigeria | D906: MOVEMENT, EMERGENCY AND POST-CRISIS MIGRATION MANAGEMENT | E906: Nigeria | F906: 4500359162 | H906: Entity Grants | I906: CONCERN FOR WOMEN AND CHILDREN | J906: Nigeria | K906: 57366 | L906: Yes | M906: {=INDEX('Org List'!$A$2:$C$1005,MATCH(Consolidated!I906&Consolidated!J906,'Org List'!$A$2:$A$1005&'Org List'!$B$2:$B$1005,0),3)} -> NGOs: National
